<?xml version='1.0'?>

<robot name="navibot">

  <!--xacro:property name="cameraSize" value="0.05"/>
  <xacro:property name="cameraMass" value="0.1"/>
  <xacro:property name="laserSize" value="0.05"/>
  <xacro:property name="laserMass" value="0.1"/-->

  <material name="black">
    <color rgba="0.0 0.0 0.0 1.0"/>
  </material>

  <material name="blue">
    <color rgba="0.0 0.0 0.8 1.0"/>
  </material>

  <material name="green">
    <color rgba="0.0 0.8 0.0 1.0"/>
  </material>

  <material name="grey">
    <color rgba="0.2 0.2 0.2 1.0"/>
  </material>

  <material name="orange">
    <color rgba="${255/255} ${108/255} ${10/255} 1.0"/>
  </material>

  <material name="brown">
    <color rgba="${222/255} ${207/255} ${195/255} 1.0"/>
  </material>

  <material name="red">
    <color rgba="0.8 0.0 0.0 1.0"/>
  </material>

  <material name="white">
    <color rgba="1.0 1.0 1.0 1.0"/>
  </material>


  <link name='chassis'>
    <pose>0 0 0.1 0 0 0</pose>

    <inertial>
      <mass value="10.0"/>
      <origin xyz="0.0 0 0.1" rpy=" 0 0 0"/>
      <inertia
          ixx="0.1" ixy="0" ixz="0"
          iyy="0.1" iyz="0"
          izz="0.1"
      />
    </inertial>
    <collision name='chassis_collision'>
      <geometry>
        <box size=".4 .2 .1"/>
      </geometry>
    </collision>

    <visual name='chassis_visual'>
      <origin xyz="0 0 0" rpy=" 0 0 0"/>
      <geometry>
        <box size=".4 .2 .1"/>
      </geometry>
    </visual>
  </link>

  <link name='caster_back'>
    <inertial>
      <mass value="1."/>
      <origin xyz="0.0 0 0.1" rpy=" 0 0 0"/>
      <inertia
          ixx="0.1" ixy="0" ixz="0"
          iyy="0.1" iyz="0"
          izz="0.1"
      />
    </inertial>

    <collision name='caster_back_collision'>
      <origin xyz="0.0 0 0.0" rpy=" 0 0 0"/>
      <geometry>
        <sphere radius="0.05"/>
      </geometry>
      <surface>
        <friction>
          <ode>
            <mu>1000</mu>
            <mu2>1000</mu2>
            <slip1>1000.0</slip1>
            <slip2>1000.0</slip2>
          </ode>
        </friction>
      </surface>
    </collision>
  
    <visual name='caster_back_visual'>
      <origin xyz="0.0 0 0.0" rpy=" 0 0 0"/>
      <geometry>
        <sphere radius="0.05"/>
      </geometry>
    </visual>
  </link>

  <joint type="continuous" name="chassis_caster_back_x">
    <origin xyz="-0.15 0 -0.05" rpy="0 0 0"/>
    <child link="caster_back"/>
    <parent link="chassis"/>
    <axis xyz="1 0 0" rpy="0 0 0"/>
    <limit effort="10000" velocity="1000"/>
    <joint_properties damping="1.0" friction="1.0"/>
  </joint>

  <link name='caster_back2'>
    <inertial>
      <mass value="0.01"/>
      <origin xyz="0 0 0" rpy=" 0 0 0"/>
      <inertia
          ixx="0.0001" ixy="0" ixz="0"
          iyy="0.0001" iyz="0"
          izz="0.0001"
      />
    </inertial>
    <visual name='caster_back_visual2'>
      <origin xyz="0 0 0" rpy=" 0 0 0"/>
      <geometry>
        <sphere radius="0.02"/>
      </geometry>
    </visual>
  </link>

  <joint type="continuous" name="chassis_caster_back_y">
    <origin xyz="0.0 0 0.0" rpy="0 0 0"/>
    <child link="caster_back2"/>
    <parent link="caster_back"/>
    <axis xyz="0 1 0" rpy="0 0 0"/>
    <limit effort="10000" velocity="1000"/>
    <joint_properties damping="1.0" friction="1.0"/>
  </joint>

  <link name='caster_back3'>
    <inertial>
      <mass value="0.01"/>
      <origin xyz="0 0 0" rpy=" 0 0 0"/>
      <inertia
          ixx="0.0001" ixy="0" ixz="0"
          iyy="0.0001" iyz="0"
          izz="0.0001"
      />
    </inertial>
    <visual name='caster_back_visual3'>
      <origin xyz="0 0 0" rpy=" 0 0 0"/>
      <geometry>
        <sphere radius="0.01"/>
      </geometry>
    </visual>
  </link>

  <joint type="continuous" name="chassis_caster_back_z">
    <origin xyz="0.0 0 0.0" rpy="0 0 0"/>
    <child link="caster_back3"/>
    <parent link="caster_back2"/>
    <axis xyz="0 0 1" rpy="0 0 0"/>
    <limit effort="10000" velocity="1000"/>
    <joint_properties damping="1.0" friction="1.0"/>
  </joint>
  

  <link name='caster_front'>
    <inertial>
      <mass value="1."/>
      <origin xyz="0.0 0 0.1" rpy=" 0 0 0"/>
      <inertia
          ixx="0.1" ixy="0" ixz="0"
          iyy="0.1" iyz="0"
          izz="0.1"
      />
    </inertial>
    <collision name='caster_front_collision'>
      <origin xyz="0 0 0" rpy=" 0 0 0"/>
      <geometry>
        <sphere radius="0.05"/>
      </geometry>
      <surface>
        <friction>
          <ode>
            <mu>1000</mu>
            <mu2>1000</mu2>
            <slip1>1000.0</slip1>
            <slip2>1000.0</slip2>
          </ode>
        </friction>
      </surface>
    </collision>

    <visual name='caster_front_visual'>
      <origin xyz="0 0 0" rpy=" 0 0 0"/>
      <geometry>
        <sphere radius="0.05"/>
      </geometry>
    </visual>

  </link>

 <joint type="continuous" name="chassis_caster_front_x">
    <origin xyz="0.15 0 -0.05" rpy="0 0 0"/>
    <child link="caster_front"/>
    <parent link="chassis"/>
    <axis xyz="1 0 0" rpy="0 0 0"/>
    <limit effort="10000" velocity="1000"/>
    <joint_properties damping="1.0" friction="1.0"/>
  </joint>

  <link name='caster_front2'>
    <inertial>
      <mass value="0.01"/>
      <origin xyz="0 0 0" rpy=" 0 0 0"/>
      <inertia
          ixx="0.0001" ixy="0" ixz="0"
          iyy="0.0001" iyz="0"
          izz="0.0001"
      />
    </inertial>
    <visual name='caster_front_visual2'>
      <origin xyz="0 0 0" rpy=" 0 0 0"/>
      <geometry>
        <sphere radius="0.02"/>
      </geometry>
    </visual>
  </link>

  <joint type="continuous" name="chassis_caster_front_y">
    <origin xyz="0 0 0" rpy="0 0 0"/>
    <child link="caster_front2"/>
    <parent link="caster_front"/>
    <axis xyz="0 1 0" rpy="0 0 0"/>
    <limit effort="10000" velocity="1000"/>
    <joint_properties damping="1.0" friction="1.0"/>
  </joint>
  

  <link name='caster_front3'>
    <inertial>
      <mass value="0.01"/>
      <origin xyz="0 0 0" rpy=" 0 0 0"/>
      <inertia
          ixx="0.0001" ixy="0" ixz="0"
          iyy="0.0001" iyz="0"
          izz="0.0001"
      />
    </inertial>
    <visual name='caster_front_visual3'>
      <origin xyz="0 0 0" rpy=" 0 0 0"/>
      <geometry>
        <sphere radius="0.01"/>
      </geometry>
    </visual>
  </link>

  <joint type="continuous" name="chassis_caster_front_z">
    <origin xyz="0 0 0" rpy="0 0 0"/>
    <child link="caster_front3"/>
    <parent link="caster_front2"/>
    <axis xyz="0 0 1" rpy="0 0 0"/>
    <limit effort="10000" velocity="1000"/>
    <joint_properties damping="1.0" friction="1.0"/>
  </joint>



  <link name="left_wheel">
    <!--origin xyz="0.1 0.13 0.1" rpy="0 1.5707 1.5707"/-->
    <collision name="collision">
      <origin xyz="0 0 0" rpy="0 1.5707 1.5707"/>
      <geometry>
        <cylinder radius="0.1" length="0.05"/>
      </geometry>
      <surface>
        <friction>
          <ode>
            <mu>1000</mu>
            <mu2>1000</mu2>
            <slip1>1000.0</slip1>
            <slip2>1000.0</slip2>
          </ode>
        </friction>
      </surface>
    </collision>
    <visual name="left_wheel_visual">
      <origin xyz="0 0 0" rpy="0 1.5707 1.5707"/>
      <geometry>
        <cylinder radius="0.1" length="0.05"/>
      </geometry>
    </visual>
    <inertial>
      <origin xyz="0 0 0" rpy="0 1.5707 1.5707"/>
      <mass value="3."/>
      <inertia
        ixx=".1" ixy="0.0" ixz="0.0"
        iyy=".1" iyz="0.0"
        izz=".1"/>
    </inertial>
  </link>

  <link name="right_wheel">
    <!--origin xyz="0.1 -0.13 0.1" rpy="0 1.5707 1.5707"/-->
    <collision name="collision">
      <origin xyz="0 0 0" rpy="0 1.5707 1.5707"/>
      <geometry>
        <cylinder radius="0.1" length="0.05"/>
      </geometry>
      <surface>
        <friction>
          <ode>
            <mu>1000</mu>
            <mu2>1000</mu2>
            <slip1>1000.0</slip1>
            <slip2>1000.0</slip2>
          </ode>
        </friction>
      </surface>
    </collision>
    <visual name="right_wheel_visual">
      <origin xyz="0 0 0" rpy="0 1.5707 1.5707"/>
      <geometry>
        <cylinder radius="0.1" length="0.05"/>
      </geometry>
    </visual>
    <inertial>
      <origin xyz="0 0 0" rpy="0 1.5707 1.5707"/>
      <mass value="3."/>
      <inertia
        ixx=".1" ixy="0.0" ixz="0.0"
        iyy=".1" iyz="0.0"
        izz=".1"/>
    </inertial>
  </link>


  <joint type="continuous" name="left_wheel_hinge">
    <origin xyz="0 0.15 0" rpy="0 0 0"/>
    <!--origin xyz="0.1 0.13 0" rpy="0 1.5707 1.5707"/-->
    <child link="left_wheel"/>
    <parent link="chassis"/>
    <axis xyz="0 1 0" rpy="0 0 0"/>
    <limit effort="10000" velocity="1000"/>
    <joint_properties damping="1.0" friction="1.0"/>
  </joint>

  <joint type="continuous" name="right_wheel_hinge">
    <origin xyz="0 -0.15 0" rpy="0 0 0"/>
    <!--origin xyz="0.1 -0.13 0" rpy="0 1.5707 1.5707"/-->
    <child link="right_wheel"/>
    <parent link="chassis"/>
    <axis xyz="0 1 0" rpy="0 0 0"/>
    <limit effort="10000" velocity="1000"/>
    <joint_properties damping="1.0" friction="1.0"/>
  </joint>


  <joint name="hokuyo_joint" type="fixed">
    <axis xyz="0 1 0" />
    <origin xyz=".2 0 0" rpy="0 0 0"/>
    <parent link="chassis"/>
    <child link="hokuyo"/>
  </joint>

  <!-- Hokuyo Laser -->
  <link name="hokuyo">
    <collision name="hokuyo_collision">
      <origin xyz="0 0 0" rpy="0 0 0"/>
      <geometry>
        <sphere radius="0.05"/>
      </geometry>
    </collision>

    <visual>
      <origin xyz="0 0 0" rpy="0 0 0"/>
      <geometry>
        <sphere radius="0.05"/>
      </geometry>
    </visual>

    <inertial>
      <mass value="1e-5" />
      <origin xyz="0 0 0" rpy="0 0 0"/>
      <inertia ixx="1e-6" ixy="0" ixz="0" iyy="1e-6" iyz="0" izz="1e-6" />
    </inertial>
  </link>

  <!--transmission name="trans_left_wheel">
    <type>transmission_interface/SimpleTransmission</type>
    <joint name="left_wheel_hinge">
      <hardwareInterface>hardware_interface/EffortJointInterface</hardwareInterface>
    </joint>
    <actuator name="motor_left_wheel">
      <hardwareInterface>hardware_interface/EffortJointInterface</hardwareInterface>
      <mechanicalReduction>1</mechanicalReduction>
    </actuator>
  </transmission>

  <transmission name="trans_right_wheel">
    <type>transmission_interface/SimpleTransmission</type>
    <joint name="right_wheel_hinge">
      <hardwareInterface>hardware_interface/EffortJointInterface</hardwareInterface>
    </joint>
    <actuator name="motor_right_wheel">
      <hardwareInterface>hardware_interface/EffortJointInterface</hardwareInterface>
      <mechanicalReduction>1</mechanicalReduction>
    </actuator>
  </transmission-->


 <gazebo>
    <plugin name="differential_drive_controller" filename="libgazebo_ros_diff_drive.so">
      <legacyMode>false</legacyMode>
      <alwaysOn>true</alwaysOn>
      <updateRate>10</updateRate>
      <leftJoint>left_wheel_hinge</leftJoint>
      <rightJoint>right_wheel_hinge</rightJoint>
      <wheelSeparation>0.4</wheelSeparation>
      <wheelDiameter>0.2</wheelDiameter>
      <torque>10</torque>
      <commandTopic>/navibot/velocity</commandTopic>
      <odometryTopic>odom</odometryTopic>
      <odometryFrame>odom</odometryFrame>
      <robotBaseFrame>chassis</robotBaseFrame>
    </plugin>
</gazebo>

  <!--gazebo>
  <plugin name="gazebo_ros_control" filename="libgazebo_ros_control.so">
    <robotNamespace>/navibot</robotNamespace>
    <updateRate>100</updateRate>
  </plugin>
</gazebo-->

  <gazebo reference="chassis">
    <material>Gazebo/Orange</material>
    <!-- contact sensor -->
    <sensor type="contact" name="chassis_contact_sensor">
      <update_rate>100</update_rate>
      <always_on>1</always_on>
      <contact>
        <collision>chassis_collision_collision</collision>
      </contact>
      <plugin name="gazebo_ros_bumper_controller" filename="libgazebo_ros_bumper.so">
            <alwaysOn>true</alwaysOn>
            <updateRate>100</updateRate>
            <bumperTopicName>/navibot/chassis_bumper</bumperTopicName>
            <frameName>chassis</frameName>
      </plugin>
    </sensor>
  </gazebo>

  <gazebo reference="left_wheel">
    <!-- contact sensor -->
    <sensor type="contact" name="chassis_contact_sensor">
      <update_rate>20.0</update_rate>
      <always_on>1</always_on>
      <contact>
        <collision>left_wheel_collision_collision</collision>
      </contact>
      <plugin name="gazebo_ros_bumper_controller" filename="libgazebo_ros_bumper.so">
            <alwaysOn>true</alwaysOn>
            <updateRate>20.0</updateRate>
            <bumperTopicName>/navibot/left_wheel_bumper</bumperTopicName>
            <frameName>left_wheel</frameName>
      </plugin>
    </sensor>
  </gazebo>

  <gazebo reference="right_wheel">
    <!-- contact sensor -->
    <sensor type="contact" name="chassis_contact_sensor">
      <update_rate>20.0</update_rate>
      <always_on>1</always_on>
      <contact>
        <collision>right_wheel_collision_collision</collision>
      </contact>
      <plugin name="gazebo_ros_bumper_controller" filename="libgazebo_ros_bumper.so">
            <alwaysOn>true</alwaysOn>
            <updateRate>20.0</updateRate>
            <bumperTopicName>/navibot/right_wheel_bumper</bumperTopicName>
            <frameName>right_wheel</frameName>
      </plugin>
    </sensor>
  </gazebo>

  <!--gazebo reference="camera">
    <material>Gazebo/Black</material>
    <sensor type="camera" name="camera1">
      <update_rate>30.0</update_rate>
      <camera name="head">
        <horizontal_fov>1.3962634</horizontal_fov>
        <image>
          <width>800</width>
          <height>800</height>
          <format>R8G8B8</format>
        </image>
        <clip>
          <near>0.02</near>
          <far>300</far>
        </clip>
      </camera>
      <plugin name="camera_controller" filename="libgazebo_ros_camera.so">
        <alwaysOn>true</alwaysOn>
        <updateRate>0.0</updateRate>
        <cameraName>navibot/camera1</cameraName>
        <imageTopicName>image_raw</imageTopicName>
        <cameraInfoTopicName>camera_info</cameraInfoTopicName>
        <frameName>camera</frameName>
        <hackBaseline>0.07</hackBaseline>
        <distortionK1>0.0</distortionK1>
        <distortionK2>0.0</distortionK2>
        <distortionK3>0.0</distortionK3>
        <distortionT1>0.0</distortionT1>
        <distortionT2>0.0</distortionT2>
      </plugin>
    </sensor>
  </gazebo-->

  <!-- hokuyo -->
  <gazebo reference="hokuyo">
    <sensor type="gpu_ray" name="hokuyo_sensor">
      <pose>0 0 0 0 0 0</pose>
      <visualize>true</visualize>
      <update_rate>40</update_rate>
      <ray>
        <scan>
          <horizontal>
            <samples>7</samples>
            <resolution>1</resolution>
            <min_angle>-1.570796</min_angle>
            <max_angle>1.570796</max_angle>
          </horizontal>
        </scan>
        <range>
          <min>0.10</min>
          <max>30.0</max>
          <resolution>0.01</resolution>
        </range>
        <noise>
          <type>gaussian</type>
          <!-- Noise parameters based on published spec for Hokuyo laser
               achieving "+-30mm" accuracy at range < 10m.  A mean of 0.0m and
               stddev of 0.01m will put 99.7% of samples within 0.03m of the true
               reading. -->
          <mean>0.0</mean>
          <stddev>0.01</stddev>
        </noise>
      </ray>
      <plugin name="gazebo_ros_hokuyo_controller" filename="libgazebo_ros_gpu_laser.so">
        <topicName>/navibot/laser/scan</topicName>
        <frameName>hokuyo</frameName>
      </plugin>
    </sensor>

    <!-- contact sensor -->
    <!--sensor type="contact" name="hokuyo_contact_sensor">
      <update_rate>20.0</update_rate>
      <always_on>1</always_on>
      <contact>
        <collision>hokuyo_collision_collision</collision>
      </contact>
      <plugin name="gazebo_ros_bumper_controller" filename="libgazebo_ros_bumper.so">
            <alwaysOn>true</alwaysOn>
            <updateRate>20.0</updateRate>
            <bumperTopicName>/navibot/front_bumper</bumperTopicName>
            <frameName>hokuyo_sensor</frameName>
      </plugin>
    </sensor-->
  </gazebo>


</robot>